<?xml version="1.0"?>
<robot name="simple_arm">

  <!-- Base Plate -->
  <link name="base_plate">
    <visual>      
    <geometry>
        <cylinder radius="1" length="0.1"/>
      </geometry>
      <material name="gray">
        <color rgba="0 0 0 .5"/>
      </material>
    </visual>
  </link>

  <!-- Base Mount -->
  <link name="base_mount">
    <visual>
      <origin xyz="0 0 .1" rpy="0 0 0"/>
      <geometry>
        <box size="0.1 0.1 .2"/>
      </geometry>
      <material name="red">
        <color rgba="1 0 0 1"/>
      </material>
    </visual>
  </link>

  <!-- Arm1 -->
  <link name="arm1">
    <visual>
      <origin xyz="0 0 .2" rpy="0 0 0"/>
      <geometry>
        <box size="0.1 0.1 0.4"/>
      </geometry>
	   <material name="blue">
        <color rgba="0 0 1 1"/>
      </material>
    </visual>
  </link>

  <!-- Arm2 -->
  <link name="arm2">
    <visual>
      <origin xyz="0 0 .1" rpy="0 0 0"/>
      <geometry>
        <box size="0.1 0.1 0.2"/>
      </geometry>
	   <material name="green">
        <color rgba="0 1 0 1"/>
      </material>
    </visual>
  </link>


  <!-- Joints -->
  <!-- Base mount -->
  <joint name="joint1" type="fixed">
    <parent link="base_plate"/>
    <child link="base_mount"/>
    <origin xyz="0 0 0" rpy="0 0 0"/>
    <axis xyz="0 0 0"/>
  </joint>
  <!-- Base to Upper Arm Joint -->
  <joint name="joint2" type="revolute">
    <parent link="base_mount"/>
    <child link="arm1"/>
    <origin xyz="0 0 .2" rpy="0 0 0"/>
    <axis xyz="0 1 0"/>
    <limit lower="-1.57" upper="1.57" effort="1000" velocity="0.5"/>
  </joint>
  <!-- Elbow Joint -->
  <joint name="joint3" type="revolute">
    <parent link="arm1"/>
    <child link="arm2"/>
    <origin xyz="0.0 0. 0.4" rpy="0 0 0"/> <!-- Adjusted to the end of the upper arm -->
    <axis xyz="0 1 0"/> <!-- Rotate around the Y-axis -->
    <limit lower="-1.57" upper="1.57" effort="1000" velocity="1.0"/>
  </joint>


</robot>

